<?xml version = "1.0"?>
<robot name="half_humman">

    <material name="orange">
        <color rgba="1.0 1.0 0.0 1.0"/>
    </material>

    <material name="red">
        <color rgba="1.0 0.27 0.0 1.0"/>
    </material>

    <material name="green">
        <color rgba="0.0 1.0 0.0 1.0"/>
    </material>

    <material name="blue">
        <color rgba="0.0 0.0 1.0 1.0"/>
    </material>

    <link name="base_link"/>

    <joint name="joint_wolrd" type="fixed">
        <parent link="base_link"/>
        <child link="chest"/>
        <origin xyz="0 0 0.75" rpy="0 0 0"/>
    </joint>

    <link name="chest">
        <collision>
            <origin xyz="0 0 -0.05" rpy="0 0 0"/>
            <geometry>
                <box size="0.2 0.4 0.1"/>
            </geometry>
        </collision>

        <visual>
            <origin xyz="0 0 -0.05" rpy="0 0 0"/>
            <geometry>
                <box size="0.2 0.4 0.1"/>
            </geometry>
            <material name="orange"/>
        </visual>

        <inertial>
            <origin xyz="0 0 -0.05" rpy="0 0 0"/>
            <mass value="50"/>
            <inertia
              ixx="0.7083"
              iyy="0.2083"
              izz="0.8333"
              ixy="0"
              ixz="0"
              iyz="0"
            />
        </inertial>
    </link>
    <!--left leg-->
    <joint name="hip_left" type="revolute">
        <parent link="chest"/>
        <child link="hip_left_link"/>
        <origin xyz="0 0.2 -0.15" rpy="0 0 0"/>
        <axis xyz="0 -1 0" />
        <limit lower="-1.57" upper="1.57" effort="10.0" velocity="5.0"/>
        <dynamics damping="0.0" friction="0.0"/>
    </joint>

    <link name="hip_left_link">
        <collision>
            <origin xyz="0 0 -0.1" rpy="0 0 0"/>
            <geometry>
                <box size="0.1 0.1 0.2"/>
            </geometry>
        </collision>

        <visual>
            <origin xyz="0 0 -0.1" rpy="0 0 0"/>
            <geometry>
                <box size="0.1 0.1 0.2"/>
            </geometry>
            <material name="blue"/>
        </visual>

        <inertial>
            <origin xyz="0 0 -0.1" rpy="0 0 0"/>
            <mass value="10"/>
            <inertia
            ixx="0.0416"
            iyy="0.0416"
            izz="0.0167"
            ixy="0"
            ixz="0"
            iyz="0"
            />
        </inertial>
    </link>

    <joint name="knee_left" type="revolute">
        <parent link="hip_left_link"/>
        <child link="leg_left_link"/>
        <origin xyz="0 0 -0.25" rpy="0 0 0"/>
        <axis xyz="0 -1 0" />
        <limit lower="-1.57" upper="1.57" effort="10.0" velocity="5.0"/>
        <dynamics damping="0.0" friction="0.0"/>
    </joint>

    <link name="leg_left_link">
        <collision>
            <origin xyz="0 0 -0.1" rpy="0 0 0"/>
            <geometry>
                <box size="0.1 0.1 0.2"/>
            </geometry>
        </collision>

        <visual>
            <origin xyz="0 0 -0.1" rpy="0 0 0"/>
            <geometry>
                <box size="0.1 0.1 0.2"/>
            </geometry>
        </visual>

        <inertial>
            <origin xyz="0 0 -0.1" rpy="0 0 0"/>
            <mass value="10"/>
            <inertia
            ixx="0.0416"
            iyy="0.0416"
            izz="0.0167"
            ixy="0"
            ixz="0"
            iyz="0"
            />
        </inertial>
    </link>

    <joint name="ankle_left" type="revolute">
        <parent link="leg_left_link"/>
        <child link="foot_left_link"/>
        <origin xyz="0 0 -0.25" rpy="0 0 0"/>
        <axis xyz="0 -1 0" />
        <limit lower="-0.78" upper="0.78" effort="10.0" velocity="5.0"/>
        <dynamics damping="0.0" friction="0.0"/>
    </joint>

    <link name="foot_left_link">
        <collision>
            <origin xyz="0 0 -0.025" rpy="0 0 0"/>
            <geometry>
                <box size="0.25 0.15 0.05"/>
            </geometry>
        </collision>

        <visual>
            <origin xyz="0 0 -0.025" rpy="0 0 0"/>
            <geometry>
                <box size="0.25 0.15 0.05"/>
            </geometry>
            <material name="red"/>
        </visual>

        <inertial>
            <origin xyz="0 0 -0.025" rpy="0 0 0"/>
            <mass value="10"/>
            <inertia
              ixx="0.0208"
              iyy="0.0542"
              izz="0.0708"
              ixy="0"
              ixz="0"
              iyz="0"
            />
        </inertial>
    </link>
    
    <!--right leg-->
    <joint name="hip_right" type="revolute">
        <parent link="chest"/>
        <child link="hip_right_link"/>
        <origin xyz="0 -0.2 -0.15" rpy="0 0 0"/>
        <limit lower="-1.57" upper="1.57" effort="10.0" velocity="5.0"/>
        <axis xyz="0 -1 0" />
        <dynamics damping="0.0" friction="0.0"/>
    </joint>

    <link name="hip_right_link">
        <collision>
            <origin xyz="0 0 -0.1" rpy="0 0 0"/>
            <geometry>
                <box size="0.1 0.1 0.2"/>
            </geometry>
        </collision>

        <visual>
            <origin xyz="0 0 -0.1" rpy="0 0 0"/>
            <geometry>
                <box size="0.1 0.1 0.2"/>
            </geometry>
            <material name="blue"/>
        </visual>

        <inertial>
            <origin xyz="0 0 -0.1" rpy="0 0 0"/>
            <mass value="10"/>
            <inertia
            ixx="0.0416"
            iyy="0.0416"
            izz="0.0167"
            ixy="0"
            ixz="0"
            iyz="0"
            />
        </inertial>
    </link>

    <joint name="knee_right" type="revolute">
        <parent link="hip_right_link"/>
        <child link="leg_right_link"/>
        <origin xyz="0 0 -0.25" rpy="0 0 0"/>
        <limit lower="-1.57" upper="1.57" effort="10.0" velocity="5.0"/>
        <axis xyz="0 -1 0" />
        <dynamics damping="0.0" friction="0.0"/>
    </joint>

    <link name="leg_right_link">
        <collision>
            <origin xyz="0 0 -0.1" rpy="0 0 0"/>
            <geometry>
                <box size="0.1 0.1 0.2"/>
            </geometry>
        </collision>

        <visual>
            <origin xyz="0 0 -0.1" rpy="0 0 0"/>
            <geometry>
                <box size="0.1 0.1 0.2"/>
            </geometry>
        </visual>

        <inertial>
            <origin xyz="0 0 -0.1" rpy="0 0 0"/>
            <mass value="10"/>
            <inertia
            ixx="0.0416"
            iyy="0.0416"
            izz="0.0167"
            ixy="0"
            ixz="0"
            iyz="0"
            />
        </inertial>
    </link>
    
    <joint name="ankle_right" type="revolute">
        <parent link="leg_right_link"/>
        <child link="foot_right_link"/>
        <origin xyz="0 0 -0.25" rpy="0 0 0"/>
        <limit lower="-0.78" upper="0.78" effort="10.0" velocity="5.0"/>
        <axis xyz="0 -1 0" />
        <dynamics damping="0.0" friction="0.0"/>
    </joint>

    <link name="foot_right_link">
        <collision>
            <origin xyz="0 0 -0.025" rpy="0 0 0"/>
            <geometry>
                <box size="0.25 0.15 0.05"/>
            </geometry>
        </collision>

        <visual>
            <origin xyz="0 0 -0.025" rpy="0 0 0"/>
            <geometry>
                <box size="0.25 0.15 0.05"/>
            </geometry>
            <material name="red"/>
        </visual>

        <inertial>
            <origin xyz="0 0 -0.025" rpy="0 0 0"/>
            <mass value="10"/>
            <inertia
              ixx="0.0208"
              iyy="0.0542"
              izz="0.0708"
              ixy="0"
              ixz="0"
              iyz="0"
            />
        </inertial>
    </link>

    <!--right sensor-->
    <joint name="right_sensor_1" type="fixed">
        <parent link="foot_right_link"/>
        <child link="fix_foot_right_1"/>
        <origin xyz="0.125 0.075 -0.075" rpy="0 0 0"/>
    </joint>

    <link name="fix_foot_right_1">
        <collision>
            <origin xyz="0 0 0" rpy="0 0 0"/>
            <geometry>
                <sphere radius="0.025"/>
            </geometry>
        </collision>

        <visual>
            <origin xyz="0 0 0" rpy="0 0 0"/>
            <geometry>
                <sphere radius="0.025"/>
            </geometry>
            <material name="green"/>
        </visual>

        <inertial>
            <origin xyz="0 0 0" rpy="0 0 0"/>
            <mass value="1"/>
            <inertia
              ixx="0.00025"
              iyy="0.00025"
              izz="0.00025"
              ixy="0"
              ixz="0"
              iyz="0"
            />
        </inertial>
    </link>

    <joint name="right_sensor_2" type="fixed">
        <parent link="foot_right_link"/>
        <child link="fix_foot_right_2"/>
        <origin xyz="-0.125 0.075 -0.075" rpy="0 0 0"/>
    </joint>

    <link name="fix_foot_right_2">
        <collision>
            <origin xyz="0 0 0" rpy="0 0 0"/>
            <geometry>
                <sphere radius="0.025"/>
            </geometry>
        </collision>

        <visual>
            <origin xyz="0 0 0" rpy="0 0 0"/>
            <geometry>
                <sphere radius="0.025"/>
            </geometry>
            <material name="green"/>
        </visual>

        <inertial>
            <origin xyz="0 0 0" rpy="0 0 0"/>
            <mass value="1"/>
            <inertia
              ixx="0.00025"
              iyy="0.00025"
              izz="0.00025"
              ixy="0"
              ixz="0"
              iyz="0"
            />
        </inertial>
    </link>

    <joint name="right_sensor_3" type="fixed">
        <parent link="foot_right_link"/>
        <child link="fix_foot_right_3"/>
        <origin xyz="-0.125 -0.075 -0.075" rpy="0 0 0"/>
    </joint>

    <link name="fix_foot_right_3">
        <collision>
            <origin xyz="0 0 0" rpy="0 0 0"/>
            <geometry>
                <sphere radius="0.025"/>
            </geometry>
        </collision>

        <visual>
            <origin xyz="0 0 0" rpy="0 0 0"/>
            <geometry>
                <sphere radius="0.025"/>
            </geometry>
            <material name="green"/>
        </visual>

        <inertial>
            <origin xyz="0 0 0" rpy="0 0 0"/>
            <mass value="1"/>
            <inertia
              ixx="0.00025"
              iyy="0.00025"
              izz="0.00025"
              ixy="0"
              ixz="0"
              iyz="0"
            />
        </inertial>
    </link>

    <joint name="right_sensor_4" type="fixed">
        <parent link="foot_right_link"/>
        <child link="fix_foot_right_4"/>
        <origin xyz="0.125 -0.075 -0.075" rpy="0 0 0"/>
    </joint>

    <link name="fix_foot_right_4">
        <collision>
            <origin xyz="0 0 0" rpy="0 0 0"/>
            <geometry>
                <sphere radius="0.025"/>
            </geometry>
        </collision>

        <visual>
            <origin xyz="0 0 0" rpy="0 0 0"/>
            <geometry>
                <sphere radius="0.025"/>
            </geometry>
            <material name="green"/>
        </visual>

        <inertial>
            <origin xyz="0 0 0" rpy="0 0 0"/>
            <mass value="1"/>
            <inertia
              ixx="0.00025"
              iyy="0.00025"
              izz="0.00025"
              ixy="0"
              ixz="0"
              iyz="0"
            />
        </inertial>
    </link>

    <!--left sensor-->
    <joint name="left_sensor_1" type="fixed">
        <parent link="foot_left_link"/>
        <child link="fix_foot_left_1"/>
        <origin xyz="-0.125 -0.075 -0.075" rpy="0 0 0"/>
    </joint>

    <link name="fix_foot_left_1">
        <collision>
            <origin xyz="0 0 0" rpy="0 0 0"/>
            <geometry>
                <sphere radius="0.025"/>
            </geometry>
        </collision>

        <visual>
            <origin xyz="0 0 0" rpy="0 0 0"/>
            <geometry>
                <sphere radius="0.025"/>
            </geometry>
            <material name="green"/>
        </visual>

        <inertial>
            <origin xyz="0 0 0" rpy="0 0 0"/>
            <mass value="1"/>
            <inertia
              ixx="0.00025"
              iyy="0.00025"
              izz="0.00025"
              ixy="0"
              ixz="0"
              iyz="0"
            />
        </inertial>
    </link>

    <joint name="left_sensor_2" type="fixed">
        <parent link="foot_left_link"/>
        <child link="fix_foot_left_2"/>
        <origin xyz="-0.125 0.075 -0.075" rpy="0 0 0"/>
    </joint>

    <link name="fix_foot_left_2">
        <collision>
            <origin xyz="0 0 0" rpy="0 0 0"/>
            <geometry>
                <sphere radius="0.025"/>
            </geometry>
        </collision>

        <visual>
            <origin xyz="0 0 0" rpy="0 0 0"/>
            <geometry>
                <sphere radius="0.025"/>
            </geometry>
            <material name="green"/>
        </visual>

        <inertial>
            <origin xyz="0 0 0" rpy="0 0 0"/>
            <mass value="1"/>
            <inertia
              ixx="0.00025"
              iyy="0.00025"
              izz="0.00025"
              ixy="0"
              ixz="0"
              iyz="0"
            />
        </inertial>
    </link>

    <joint name="left_sensor_3" type="fixed">
        <parent link="foot_left_link"/>
        <child link="fix_foot_left_3"/>
        <origin xyz="0.125 -0.075 -0.075" rpy="0 0 0"/>
    </joint>

    <link name="fix_foot_left_3">
        <collision>
            <origin xyz="0 0 0" rpy="0 0 0"/>
            <geometry>
                <sphere radius="0.025"/>
            </geometry>
        </collision>

        <visual>
            <origin xyz="0 0 0" rpy="0 0 0"/>
            <geometry>
                <sphere radius="0.025"/>
            </geometry>
            <material name="green"/>
        </visual>

        <inertial>
            <origin xyz="0 0 0" rpy="0 0 0"/>
            <mass value="1"/>
            <inertia
              ixx="0.00025"
              iyy="0.00025"
              izz="0.00025"
              ixy="0"
              ixz="0"
              iyz="0"
            />
        </inertial>
    </link>

    <joint name="left_sensor_4" type="fixed">
        <parent link="foot_left_link"/>
        <child link="fix_foot_left_4"/>
        <origin xyz="0.125 0.075 -0.075" rpy="0 0 0"/>
    </joint>

    <link name="fix_foot_left_4">
        <collision>
            <origin xyz="0 0 0" rpy="0 0 0"/>
            <geometry>
                <sphere radius="0.025"/>
            </geometry>
        </collision>

        <visual>
            <origin xyz="0 0 0" rpy="0 0 0"/>
            <geometry>
                <sphere radius="0.025"/>
            </geometry>
            <material name="green"/>
        </visual>

        <inertial>
            <origin xyz="0 0 0" rpy="0 0 0"/>
            <mass value="1"/>
            <inertia
              ixx="0.00025"
              iyy="0.00025"
              izz="0.00025"
              ixy="0"
              ixz="0"
              iyz="0"
            />
        </inertial>
    </link>

</robot>